Workbook

Sheet Исходные данные
A2: Контур 1 | B2: СО | D2: Контур 2 | E2: 0
A3: Число циркуляционных насосов | B3: 2 | D3: Число циркуляционных насосов | E3: 0
A4: Напряжение питания насосов | B4: 3x400 В | D4: Напряжение питания насосов | E4: 3x400 В
A5: Мощность насосов | B5: 6 | D5: Мощность насосов | E5: 0.37
A6: Ток насосов, А | B6: 3.2 | D6: Ток насосов, А | E6: 0.5
A7: Наличие ПЧ | B7: TRUE | D7: Наличие ПЧ | E7: FALSE
A9: Наличие подпитки | B9: FALSE
A10: Число насосов | B10: 0
A11: Напряжение питания насосов | B11: 3x400 В
A12: Мощность насосов | B12: 1.1
A13: Ток насосов | B13: 3.2
A14: Наличие ПЧ | B14: FALSE
A18: Дополнительные датчики на мониторинг (ECL-3R MM) | B18: FALSE | D18: Шкаф для БТП (ECL Connect), Если шкафов для БТП несколько, поставить галочку только для одного | E18: TRUE
A24: Результат:
A25: ='Лист подбора'!A22 -> № | B25: ='Лист подбора'!B22 -> Описание | C25: ='Лист подбора'!C22 -> Номер расчёта | D25: ='Лист подбора'!D22 -> Кол-во, шт. | E25: ='Лист подбора'!E22 -> Цена, евро без НДС | F25: ='Лист подбора'!F22 -> 0
A26: ='Лист подбора'!A23 -> 1 | B26: ='Лист подбора'!B23 -> ША | C26: ='Лист подбора'!C23 -> BST0105260002 | D26: 1 | E26: ='Лист подбора'!E23 -> 1413.9 | F26: ='Лист подбора'!F23 -> 0
A27: ='Лист подбора'!A24 -> 2 | B27: ='Лист подбора'!B24 -> ШУН контур 1 | C27: ='Лист подбора'!C24 -> BST0105263206 | D27: 1 | E27: ='Лист подбора'!E24 -> не загружена | F27: ='Лист подбора'!F24 -> 0
A28: ='Лист подбора'!A25 -> 3 | B28: ='Лист подбора'!B25 -> ШУН контур 2 | C28: ='Лист подбора'!C25 -> #N/A | D28: ='Лист подбора'!D25 -> 1 | E28: ='Лист подбора'!E25 -> 0 | F28: ='Лист подбора'!F25 -> 0
A29: ='Лист подбора'!A26 -> 4 | B29: ='Лист подбора'!B26 -> ШУН подпитка | C29: ='Лист подбора'!C26 -> #N/A | D29: ='Лист подбора'!D26 -> 1 | E29: ='Лист подбора'!E26 -> 0 | F29: ='Лист подбора'!F26 -> 0
A30: ='Лист подбора'!A27 -> 0 | B30: ='Лист подбора'!B27 -> 0 | C30: ='Лист подбора'!C27 -> 0 | D30: ='Лист подбора'!D27 -> 0 | E30: ='Лист подбора'!E27 -> 0 | F30: ='Лист подбора'!F27 -> 0

Sheet Лист подбора
A8: Номер коммерческого предложения:
A10: Дата выставления КП: | D10: 46126
A12: Срок поставки: | D12: 35 календарных дней с момента оплаты и получения согласованного задания заводу-изготовителю
A15: Условия платежа*: | D15: Предоплата 100%
A17: Условия отгрузки*: | D17: Самовывоз со склада ООО "Ридан", Московская область
A20: Согласно представленных Вами данных** подобрано следующее оборудование:
A22: № | B22: Описание | C22: Номер расчёта | D22: Кол-во, шт. | E22: Цена, евро без НДС
A23: 1 | B23: ША | C23: =IF(Подбор!E7=0,"---",Подбор!E7) -> BST0105260002 | D23: =IF(Подбор!E7=0,0,1) -> 1 | E23: =IF(Подбор!E7=0,0,IFERROR(Подбор!E8*3,Подбор!E8)) -> 1413.9
A24: 2 | B24: ШУН контур 1 | C24: =IF(Подбор!H16=0,"---",Подбор!H16) -> BST0105263206 | D24: =IF(Подбор!H16=0,0,1) -> 1 | E24: =IF(Подбор!H16=0,0,IFERROR(Подбор!H17*3,Подбор!H17)) -> не загружена
A25: 3 | B25: ШУН контур 2 | C25: =IF(Подбор!H20=0,"---",Подбор!H20) -> #N/A | D25: =IF(Подбор!H20=0,0,1) -> 1 | E25: =IF(Подбор!H20=0,0,IFERROR(Подбор!H21*3,Подбор!H21)) -> 0
A26: 4 | B26: ШУН подпитка | C26: =IF(Подбор!H25=0,"---",Подбор!H25) -> #N/A | D26: =IF(Подбор!H25=0,0,1) -> 1 | E26: =IF(Подбор!H25=0,0,IFERROR(Подбор!H26*3,Подбор!H26)) -> 0
A30: Цена указана на условиях самовывоза со склада в Московской области и действительна в течение 1 месяц с даты настоящего коммерческого предложения при условии сохранения исходных данных без изменений
A32: В стоимость входит: разработка проектной документации, комплектующие, сборка ША
A34: Эл. схема ША может быть предоставлена на согласование после разработки (по запросу)
A37: Гарантия на ША Ридан - 1 год
A39: Для покупки ША необходимо обратиться к официальным партнерам производителя в Вашем регионе.
A41: С актуальным списком всех официальных партнеров можно ознакомиться на сайте: www.ridan.ru или обратившись по тел: 7 (495) 792-57-57
A42: * - стандартные условия поставки, при дополнительном согласовании есть возможность получения специальных условий

Sheet Подбор
B1: ША | C1: Контур 1 | E1: Контур 2 | H1: Подпитка
B2: диапазон тока без ПЧ | C2: Диапазон с ПЧ | E2: диапазон тока без ПЧ | F2: Диапазон с ПЧ | H2: диапазон тока без ПЧ
B3: =IFERROR(VLOOKUP('Исходные данные'!B6,Диапазон_токов_без_ПЧ[],2,1),0) -> 5 | C3: =IFERROR(VLOOKUP('Исходные данные'!B5,Диапазон_мощностей_ЧП[],2,1),0) -> 6 | E3: =IFERROR(VLOOKUP('Исходные данные'!E6,Диапазон_токов_без_ПЧ[],2,1),0) -> 1 | F3: =IFERROR(VLOOKUP('Исходные данные'!E5,Диапазон_мощностей_ЧП[],2,1),0) -> 1 | H3: =IFERROR(VLOOKUP('Исходные данные'!B13,Диапазон_токов_без_ПЧ[],2,1),0) -> 5
B7: ША | D7: Код ША | E7: =IFERROR(D8,0) -> BST0105260002
A8: нужен | B8: контуры | D8: =IFERROR(__xludf.DUMMYFUNCTION("FILTER(База_ША,База_ША[Контур1] = B13, База_ША[Контур2] = C13, База_ША[ММ] = D13, База_ША[БТП]=E13)"),"BST0105260002") -> BST0105260002 | E8: =IFERROR(__xludf.DUMMYFUNCTION("""COMPUTED_VALUE"""),471.3) -> 471.3 | F8: =IFERROR(__xludf.DUMMYFUNCTION("""COMPUTED_VALUE"""),"СО") -> СО | G8: =IFERROR(__xludf.DUMMYFUNCTION("""COMPUTED_VALUE"""),0) -> 0 | H8: =IFERROR(__xludf.DUMMYFUNCTION("""COMPUTED_VALUE"""),0) -> 0 | I8: =IFERROR(__xludf.DUMMYFUNCTION("""COMPUTED_VALUE"""),1) -> 1
A9: =IF(ISBLANK('Исходные данные'!B2),0,1) -> 1 | B9: =IF(ISBLANK('Исходные данные'!B2),0,'Исходные данные'!B2) -> СО
B10: =IF(ISBLANK('Исходные данные'!E2),0,'Исходные данные'!E2) -> 0
B12: Контур 1 | C12: Контур 2 | D12: ММ | E12: БТП
B13: =IF(ISBLANK('Исходные данные'!B2),0,'Исходные данные'!B2) -> СО | C13: =IF(ISBLANK('Исходные данные'!E2),0,'Исходные данные'!E2) -> 0 | D13: =IF(ISBLANK('Исходные данные'!B18),0,IF('Исходные данные'!B18,1,0)) -> 0 | E13: =IF(ISBLANK('Исходные данные'!E18),0,IF('Исходные данные'!E18,1,0)) -> 1
B16: ШУН 1 | G16: Код ША | H16: =IFERROR(G17,0) -> BST0105263206
B17: Число насосов | C17: ПЧ | D17: Напряжение | E17: Диапазон | G17: =IFERROR(__xludf.DUMMYFUNCTION("FILTER(База_ШУН, База_ШУН[ПЧ]=C18, База_ШУН[Насосы]=B18, База_ШУН[Напряжение]=D18, База_ШУН[Диапазон]=E18)"),"BST0105263206") -> BST0105263206 | H17: =IFERROR(__xludf.DUMMYFUNCTION("""COMPUTED_VALUE"""),"не загружена") -> не загружена | I17: =IFERROR(__xludf.DUMMYFUNCTION("""COMPUTED_VALUE"""),1) -> 1 | J17: =IFERROR(__xludf.DUMMYFUNCTION("""COMPUTED_VALUE"""),"3x400 В") -> 3x400 В | K17: =IFERROR(__xludf.DUMMYFUNCTION("""COMPUTED_VALUE"""),2) -> 2 | L17: =IFERROR(__xludf.DUMMYFUNCTION("""COMPUTED_VALUE"""),6) -> 6
B18: =IF(OR('Исходные данные'!B3=1,'Исходные данные'!B3=2),2,0) -> 2 | C18: =IF(ISBLANK('Исходные данные'!B7),0,IF('Исходные данные'!B7,1,0)) -> 1 | D18: ='Исходные данные'!B4 -> 3x400 В | E18: =IF(C18=0,B3,C3) -> 6
B20: ШУН 2 | G20: Код ША | H20: =IFERROR(G21,0) -> #N/A
B21: Число насосов | C21: ПЧ | D21: Напряжение | E21: Диапазон | G21: =IFERROR(__xludf.DUMMYFUNCTION("FILTER(База_ШУН, База_ШУН[ПЧ]=C22, База_ШУН[Насосы]=B22, База_ШУН[Напряжение]=D22, База_ШУН[Диапазон]=E22)"),"#N/A") -> #N/A
B22: =IF(OR('Исходные данные'!E3=1,'Исходные данные'!E3=2),2,0) -> 0 | C22: =IF(ISBLANK('Исходные данные'!E7),0,IF('Исходные данные'!E7,1,0)) -> 0 | D22: ='Исходные данные'!E4 -> 3x400 В | E22: =IF(C22=0,E3,F3) -> 1
B25: ШУН подп | G25: Код ША | H25: =IFERROR(G26,0) -> #N/A
B26: Число насосов | C26: ПЧ | D26: Напряжение | E26: Диапазон | G26: =IFERROR(__xludf.DUMMYFUNCTION("FILTER(База_ШУН, База_ШУН[ПЧ]=C27, База_ШУН[Насосы]=B27, База_ШУН[Напряжение]=D27, База_ШУН[Диапазон]=E27)"),"#N/A") -> #N/A
B27: =IF(OR('Исходные данные'!B10=1,'Исходные данные'!B10=2),2,0) -> 0 | C27: =IF(ISBLANK('Исходные данные'!B14),0,IF('Исходные данные'!B14,1,0)) -> 0 | D27: ='Исходные данные'!B11 -> 3x400 В | E27: =H3 -> 5

Sheet диапазоны
A2: нижняя граница | B2: тип | C2: номинал | E2: нижняя граница | F2: тип | G2: номинал
A3: 0.4 | B3: 1 | C3: 0,4-0,63 | E3: 0 | F3: 1 | G3: 0,75 кВт
A4: 0.63 | B4: 2 | C4: 0,63-1 | E4: 0.76 | F4: 2 | G4: 1,5 кВт
A5: 1 | B5: 3 | C5: 1-1,6 | E5: 1.51 | F5: 3 | G5: 2,2 кВт
A6: 1.6 | B6: 4 | C6: 1,6-2,5 | E6: 2.21 | F6: 4 | G6: 4 кВт
A7: 2.5 | B7: 5 | C7: 2,5-4 | E7: 4.01 | F7: 5 | G7: 5,5 кВт
A8: 4 | B8: 6 | C8: 4-6,3 | E8: 5.51 | F8: 6 | G8: 7,5 кВт
A9: 6 | B9: 7 | C9: 6-10 | E9: 7.51 | F9: 7 | G9: 11 кВт
A10: 9 | B10: 8 | C10: 9-14 | E10: 11.01 | F10: 8 | G10: 15 кВт
A11: 12 | B11: 9 | C11: 13-18 | E11: 15.01 | F11: 9 | G11: 18,5 кВт
A12: 17 | B12: 10 | C12: 17-23 | E12: 18.51 | F12: 10 | G12: 22 кВт
A13: 20 | B13: 11 | C13: 20-25 | E13: 22.01 | F13: 0 | G13: не подходит
A14: 24 | B14: 12 | C14: 24-32
A15: 32 | B15: 13 | C15: 25-40
A16: 40 | B16: 14 | C16: 40-63
A17: 56 | B17: 15 | C17: 56-80
A18: 80.01 | B18: 0 | C18: не подходит
B21: Код | C21: Цена | D21: Контур1 | E21: Контур2 | F21: ММ | G21: БТП | H21: Номер следующей версии
B22: BST0105260001 | C22: 596 | D22: СО | E22: ГВС | F22: 0 | G22: 1
B23: BST0105260002 | C23: 471.3 | D23: СО | E23: 0 | F23: 0 | G23: 1
B24: BST0105260003 | C24: 471.3 | D24: ГВС | E24: 0 | F24: 0 | G24: 1
B25: BST0105260004 | C25: пока не будем использовать | D25: СО | E25: СО* | F25: 0 | G25: 1
B26: BST0105260101 | C26: 685 | D26: СО | E26: ГВС | F26: 1 | G26: 1
B27: BST0105260102 | C27: 555.8 | D27: СО | E27: 0 | F27: 1 | G27: 1
B28: BST0105260103 | C28: 555.8 | D28: ГВС | E28: 0 | F28: 1 | G28: 1
B29: BST0105260104 | C29: пока не будем использовать | D29: СО | E29: СО* | F29: 1 | G29: 1
B30: BST0105260201 | C30: 427.3 | D30: СО | E30: ГВС | F30: 0 | G30: 0
B31: BST0105260202 | C31: 284.6 | D31: СО | E31: 0 | F31: 0 | G31: 0
B32: BST0105260203 | C32: 284.6 | D32: ГВС | E32: 0 | F32: 0 | G32: 0
B38: Код | C38: Цена | D38: ПЧ | E38: Напряжение | F38: Насосы | G38: Диапазон | H38: Номер следующей версии
B39: BST0105261201 | C39: 200.1 | D39: 0 | E39: 1x230 В | F39: 2 | G39: 1
B40: BST0105261202 | C40: 200.1 | D40: 0 | E40: 1x230 В | F40: 2 | G40: 2
B41: BST0105261203 | C41: 201.4 | D41: 0 | E41: 1x230 В | F41: 2 | G41: 3
B42: BST0105261204 | C42: 201.4 | D42: 0 | E42: 1x230 В | F42: 2 | G42: 4
B43: BST0105261205 | C43: 201.4 | D43: 0 | E43: 1x230 В | F43: 2 | G43: 5
B44: BST0105261206 | C44: не загружена | D44: 0 | E44: 1x230 В | F44: 2 | G44: 6
B45: BST0105261207 | C45: не загружена | D45: 0 | E45: 1x230 В | F45: 2 | G45: 7
B46: BST0105261208 | C46: не загружена | D46: 0 | E46: 1x230 В | F46: 2 | G46: 8
B47: BST0105261209 | C47: не загружена | D47: 0 | E47: 1x230 В | F47: 2 | G47: 9
B48: BST0105261210 | C48: не загружена | D48: 0 | E48: 1x230 В | F48: 2 | G48: 10
...

Sheet Статистика применения
A1: Объект CRM | B1: Расчётчик | C1: Стандартный шкаф | D1: Почему не получилось применить стандарный шкаф
A2: 1182676 | B2: Газизов А.Р. | C2: FALSE | D2: Менеджер попросил сделать 1 общий шкаф
A3: 1104061 | B3: Газизов А.Р. | C3: FALSE | D3: Менеджер попросил сделать 1 общий шкаф
A4: 1181384 | B4: Богданов | C4: TRUE
A5: 1184344 | B5: Курбакова А.Ю. | C5: TRUE
A6: 1206953 | B6: Карелина А.Н. | C6: TRUE
A7: 1184778 | B7: Сафин И И | C7: TRUE
A8: 1184344 | B8: Карелина А.Н. | C8: TRUE
A9: 1184344 | B9: Карелина А.Н. | C9: TRUE
A10: 1184344 | B10: Карелина А.Н. | C10: TRUE
A11: 1208494 | B11: Газизов А.Р. | C11: FALSE | D11: Менеджер попросил сделать 1 общий шкаф
C12: FALSE
C13: FALSE
C14: FALSE
C15: FALSE
C16: FALSE
C17: FALSE
C18: FALSE
C19: FALSE
C20: FALSE
C21: FALSE
C22: FALSE
C23: FALSE
... C100: FALSE
